<?xml version='1.0' encoding='ASCII'?>
<sdf version="1.7">
    <model name="tugbot">
        <self_collide>false</self_collide>
        <pose>0 0 0.2 0 0 0</pose>
        <static>false</static>
        <!-- BASE -->
        <link name="base_link">
            <pose>0 0 0 0 0 0</pose>
            <inertial>
                <pose>-0.1 0 0.1 0 0 0</pose>
                <mass>46.2</mass>
                <inertia>
                    <ixx>1.55925</ixx>
                    <ixy>0</ixy>
                    <ixz>0</ixz>
                    <iyy>1.55925</iyy>
                    <iyz>0</iyz>
                    <izz>1.55925</izz>
                </inertia>
            </inertial>
            <collision name="base_link_collision">
                <pose>0 0 0 0 0 0</pose>
                <geometry>
                    <mesh>
                        <uri>meshes/base/tugbot_simp.stl</uri>
                    </mesh>
                </geometry>
            </collision>
            <visual name="base_link_visual">
                <pose>0 0 0 0 0 0</pose>
                <geometry>
                    <mesh>
                        <uri>meshes/base/tugbot_simp.dae</uri>
                    </mesh>
                </geometry>
            </visual>
            <visual name="movai_logo_visual">
                <pose>0 0 0 0 0 0</pose>
                <geometry>
                    <mesh>
                        <uri>meshes/base/movai_logo.dae</uri>
                    </mesh>
                </geometry>
                <material>
                    <diffuse>1.0 1.0 1.0</diffuse>
                    <pbr>
                        <metal>
                            <albedo_map>meshes/base/movai-logo.png</albedo_map>
                        </metal>
                    </pbr>
                </material>
            </visual>
            <visual name="light_link_visual">
                <pose>-0.1 0 0.1945 0 1.57079632679 0</pose>
                <geometry>
                    <mesh>
                        <scale>1.0 1.0 1.0</scale>
                        <uri>meshes/light_link/light_led.stl</uri>
                    </mesh>
                </geometry>
                <material>
                    <ambient>0.0 0.0 0 1</ambient>
                    <diffuse>0.0 0.0 0 1</diffuse>
                    <specular>0 0 0 1</specular>
                    <emissive>0 1 0 1</emissive>
                </material>
            </visual>
            <visual name="warnign_light_visual">
                <pose>-0.099 0 0.195 0 1.57079632679 0</pose>
                <geometry>
                    <mesh>
                        <scale>1.02 1.02 1.02</scale>
                        <uri>meshes/light_link/light.stl</uri>
                    </mesh>
                </geometry>
                <material>
                    <ambient>0.1 0.05 0 0.5</ambient>
                    <diffuse>1 0.5 0 0.5</diffuse>
                    <specular>1 0.5 0 0.5</specular>
                    <emissive>1 0.5 0 0.5</emissive>
                </material>
            </visual>
        </link>
        <link name="imu_link">
            <pose>0.14 0.02 0.25 0 0 -1.57</pose>
            <sensor name="imu" type="imu">
                <update_rate>30</update_rate>
                <visualize>false</visualize>
            </sensor>
        </link>
        <joint name="imu_link_joint" type="fixed">
            <child>imu_link</child>
            <parent>base_link</parent>
        </joint>
        <link name="warnign_light">
            <pose>-0.185 0 0.46 0 0 0</pose>
            <inertial>
                <pose>0 0 0 0 0 0</pose>
                <mass>0.1</mass>
                <inertia>
                    <ixx>0.000016875</ixx>
                    <ixy>0</ixy>
                    <ixz>0</ixz>
                    <iyy>0.00000001</iyy>
                    <iyz>0</iyz>
                    <izz>0.000016875</izz>
                </inertia>
            </inertial>
            <light name="warnign_light_lamp" type="spot">
                <pose>-0.04 0 0 0 1.57079632679 0</pose>
                <attenuation>
                    <range>5</range>
                    <linear>0</linear>
                    <constant>0.1</constant>
                    <quadratic>0.0025</quadratic>
                </attenuation>
                <diffuse>1 0.5 0 1</diffuse>
                <specular>1 0.5 0 1</specular>
                <spot>
                    <inner_angle>0.9</inner_angle>
                    <outer_angle>1.0</outer_angle>
                    <falloff>2.0</falloff>
                </spot>
                <direction>0 0 -1</direction>
                <cast_shadows>1</cast_shadows>
            </light>
        </link>
        <joint name="warnign_light_joint" type="revolute">
            <child>warnign_light</child>
            <parent>base_link</parent>
            <axis>
                <xyz>0 0 1</xyz>
                <limit>
                    <effort>1000</effort>
                    <velocity>20.0</velocity>
                </limit>
            </axis>
        </joint>
        <!-- SENSORS -->
        <link name="camera_front">
            <pose relative_to="base_link">0.0553 0 0.4323 0 0 0</pose>
            <sensor name="color" type="camera">
                <pose>0 0.0325 0.0125 0 0 0</pose>
                <update_rate>6</update_rate>
                <always_on>0</always_on>
                <camera>
                    <horizontal_fov>1.20427718</horizontal_fov>
                    <image>
                        <width>848</width>
                        <height>480</height>
                    </image>
                    <clip>
                        <near>0.1</near>
                        <far>50</far>
                    </clip>
                    <lens>
                        <intrinsics>
                            <fx>615.9603271484375</fx>
                            <fy>616.227294921875</fy>
                            <cx>419.83026123046875</cx>
                            <cy>245.1431427001953</cy>
                            <s>0</s>
                        </intrinsics>
                    </lens>
                </camera>
            </sensor>
            <sensor name="depth" type="depth_camera">
                <pose>0 0.0175 0.0125 0 0 0</pose>
                <update_rate>6</update_rate>
                <always_on>0</always_on>
                <camera>
                    <horizontal_fov>1.51843645</horizontal_fov>
                    <image>
                        <width>848</width>
                        <height>480</height>
                        <format>R_FLOAT32</format>
                    </image>
                    <clip>
                        <near>0.1</near>
                        <far>10</far>
                    </clip>
                    <lens>
                        <intrinsics>
                            <fx>421.61578369140625</fx>
                            <fy>421.61578369140625</fy>
                            <cx>422.2854309082031</cx>
                            <cy>236.57237243652344</cy>
                            <s>0</s>
                        </intrinsics>
                    </lens>
                </camera>
            </sensor>
        </link>
        <joint name="camera_front_joint" type="fixed">
            <child>camera_front</child>
            <parent>base_link</parent>
        </joint>
        <link name="camera_back">
            <pose relative_to="base_link">-0.241 0 0.2303 0 0 3.141592654</pose>
            <sensor name="color" type="camera">
                <pose>0 0.0325 0.0125 0 0 0</pose>
                <update_rate>6</update_rate>
                <always_on>0</always_on>
                <camera>
                    <horizontal_fov>1.20427718</horizontal_fov>
                    <image>
                        <width>848</width>
                        <height>480</height>
                    </image>
                    <clip>
                        <near>0.1</near>
                        <far>50</far>
                    </clip>
                    <lens>
                        <intrinsics>
                            <fx>615.9603271484375</fx>
                            <fy>616.227294921875</fy>
                            <cx>419.83026123046875</cx>
                            <cy>245.1431427001953</cy>
                            <s>0</s>
                        </intrinsics>
                    </lens>
                </camera>
            </sensor>
            <sensor name="depth" type="depth_camera">
                <pose>0 0.0175 0.0125 0 0 0</pose>
                <update_rate>6</update_rate>
                <always_on>0</always_on>
                <camera>
                    <horizontal_fov>1.51843645</horizontal_fov>
                    <image>
                        <width>848</width>
                        <height>480</height>
                        <format>R_FLOAT32</format>
                    </image>
                    <clip>
                        <near>0.1</near>
                        <far>10</far>
                    </clip>
                    <lens>
                        <intrinsics>
                            <fx>421.61578369140625</fx>
                            <fy>421.61578369140625</fy>
                            <cx>422.2854309082031</cx>
                            <cy>236.57237243652344</cy>
                            <s>0</s>
                        </intrinsics>
                    </lens>
                </camera>
            </sensor>
        </link>
        <joint name="camera_back_joint" type="fixed">
            <child>camera_back</child>
            <parent>base_link</parent>
        </joint>
        <link name="scan_front">
            <pose>0.221 0 0.1404 0 0 0</pose>
            <sensor name="scan_front" type="gpu_lidar">
                <update_rate>10</update_rate>
                <lidar>
                    <scan>
                        <horizontal>
                            <samples>674</samples>
                            <resolution>1</resolution>
                            <min_angle>-1.47043991089</min_angle>
                            <max_angle>1.47043991089</max_angle>
                        </horizontal>
                    </scan>
                    <range>
                        <min>0.01</min>
                        <max>5.0</max>
                        <resolution>0.01</resolution>
                    </range>
                </lidar>
            </sensor>
        </link>
        <joint name="scan_front_joint" type="fixed">
            <child>scan_front</child>
            <parent>base_link</parent>
        </joint>
        <link name="scan_back">
            <pose>-0.2075 0 0.205 0 0 3.141592654</pose>
            <sensor name="scan_back" type="gpu_lidar">
                <update_rate>5</update_rate>
                <lidar>
                    <scan>
                        <horizontal>
                            <samples>480</samples>
                            <resolution>1</resolution>
                            <min_angle>-1.47043991089</min_angle>
                            <max_angle>1.47043991089</max_angle>
                        </horizontal>
                    </scan>
                    <range>
                        <min>0.01</min>
                        <max>5.0</max>
                        <resolution>0.01</resolution>
                    </range>
                </lidar>
            </sensor>
        </link>
        <joint name="scan_back_joint" type="fixed">
            <child>scan_back</child>
            <parent>base_link</parent>
        </joint>
        <link name="scan_omni">
            <pose>-0.1855 0 0.5318 0 0 0</pose>
            <visual name="velodyne_base">
                <pose>0 0 -0.035 0 0 0</pose>
                <geometry>
                    <cylinder>
                        <radius>0.06</radius>
                        <length>0.0015</length>
                    </cylinder>
                </geometry>
            </visual>
            <visual name="velodyne_suport_1">
                <pose>-0.035 0.035 -0.08 0 0 0</pose>
                <geometry>
                    <cylinder>
                        <radius>0.005</radius>
                        <length>0.09</length>
                    </cylinder>
                </geometry>
            </visual>
            <visual name="velodyne_suport_2">
                <pose>-0.035 -0.035 -0.08 0 0 0</pose>
                <geometry>
                    <cylinder>
                        <radius>0.005</radius>
                        <length>0.09</length>
                    </cylinder>
                </geometry>
            </visual>
            <visual name="velodyne_suport_3">
                <pose>0.0495 0 -0.08 0 0 0</pose>
                <geometry>
                    <cylinder>
                        <radius>0.005</radius>
                        <length>0.09</length>
                    </cylinder>
                </geometry>
            </visual>
            <!-- Bottom cylinder of Ouster/Velodyne 3D Lidar -->
            <visual name="velodyne_base_link_visual_base">
                <pose>0 0 -0.035 0 0 0</pose>
                <geometry>
                    <mesh>
                        <scale>1 1 1</scale>
                        <uri>meshes/VLP16_base_1.dae</uri>
                    </mesh>
                </geometry>
            </visual>
            <!-- Top cylinder of Ouster/Velodyne 3D Lidar -->
            <visual name="velodyne_base_link_visual_sensor">
                <pose>0 0 -0.035 0 0 0</pose>
                <geometry>
                    <mesh>
                        <scale>1 1 1</scale>
                        <uri>meshes/VLP16_base_2.dae</uri>
                    </mesh>
                </geometry>
            </visual>
            <!-- Main cylinder of Ouster/Velodyne 3D Lidar -->
            <visual name="base_link_velodyne_visual_scan">
                <pose>0 0 -0.035 0 0 0</pose>
                <geometry>
                    <mesh>
                        <scale>1 1 1</scale>
                        <uri>meshes/VLP16_scan.dae</uri>
                    </mesh>
                </geometry>
            </visual>
            <sensor name="scan_omni" type="gpu_lidar">
                <update_rate>10</update_rate>
                <lidar>
                    <scan>
                        <horizontal>
                            <!-- Real samples value is 1800 -->
                            <samples>900</samples>
                            <resolution>1</resolution>
                            <min_angle>-3.141592654</min_angle>
                            <max_angle>3.141592654</max_angle>
                        </horizontal>
                        <vertical>
                            <samples>16</samples>
                            <resolution>1</resolution>
                            <min_angle>-0.261799388</min_angle>
                            <max_angle>0.261799388</max_angle>
                        </vertical>
                    </scan>
                    <range>
                        <min>0.2</min>
                        <max>100.0</max>
                        <resolution>0.01</resolution>
                    </range>
                </lidar>
            </sensor>
        </link>
        <joint name="scan_omni_joint" type="fixed">
            <child>scan_omni</child>
            <parent>base_link</parent>
        </joint>
        <!-- GRIPPER -->
        <link name="gripper">
            <pose>-0.35 0 0.1 0 0 0</pose>
            <inertial>
                <pose>0 0 0 0 -0 0</pose>
                <mass>1</mass>
                <inertia>
                    <ixx>0.001666667</ixx>
                    <ixy>0</ixy>
                    <ixz>0</ixz>
                    <iyy>0.001666667</iyy>
                    <iyz>0</iyz>
                    <izz>0.001666667</izz>
                </inertia>
            </inertial>
            <collision name="gripper_collision">
                <pose>-0.005 0 0 0 -0 0</pose>
                <max_contacts>5</max_contacts>
                <geometry>
                    <box>
                        <size>0.15 0.1 0.1</size>
                    </box>
                </geometry>
                <surface>
                    <contact>
                        <ode>
                            <kp>1000000.0</kp>
                            <kd>1</kd>
                            <min_depth>0.01</min_depth>
                            <max_vel>1</max_vel>
                        </ode>
                    </contact>
                    <friction>
                        <ode>
                            <mu>1.16</mu>
                            <mu2>1.16</mu2>
                        </ode>
                    </friction>
                </surface>
            </collision>
            <visual name="gripper_visual">
                <pose>0 0 0 -1.57079632679 0 0</pose>
                <geometry>
                    <mesh>
                        <scale>1 1 1</scale>
                        <uri>meshes/gripper2/gripper2.dae</uri>
                    </mesh>
                </geometry>
            </visual>
            <sensor name="sensor_contact" type="gpu_lidar">
                <pose>-0.075 0 0.035 0 0 3.141592654</pose>
                <update_rate>10</update_rate>
                <lidar>
                    <scan>
                        <horizontal>
                            <samples>3</samples>
                            <resolution>1</resolution>
                            <min_angle>-0.02</min_angle>
                            <max_angle>0.02</max_angle>
                        </horizontal>
                    </scan>
                    <range>
                        <min>0.001</min>
                        <max>0.01</max>
                        <resolution>0.001</resolution>
                    </range>
                </lidar>
            </sensor>
        </link>
        <joint name="gripper_joint" type="revolute">
            <pose>0.35 0 0.09 0 0 0</pose>
            <child>gripper</child>
            <parent>base_link</parent>
            <axis>
                <xyz>0 0 1</xyz>
                <limit>
                    <lower>-0.7</lower>
                    <upper>0.7</upper>
                    <effort>4</effort>
                    <velocity>0.5</velocity>
                </limit>
                <dynamics>
                    <friction>0.5</friction>
                </dynamics>
            </axis>
        </joint>
        <link name="gripper_hand">
            <pose>-0.463 0 0.1 0 0 0</pose>
            <inertial>
                <pose>0 0 0 0 0 0</pose>
                <mass>0.2</mass>
                <inertia>
                    <ixx>0.000016</ixx>
                    <ixy>0</ixy>
                    <ixz>0</ixz>
                    <iyy>0.000016</iyy>
                    <iyz>0</iyz>
                    <izz>0.000016</izz>
                </inertia>
            </inertial>
            <collision name="gripper_hand_collision">
                <pose>0.015 0 0.006 0 0 0</pose>
                <geometry>
                    <box>
                        <size>0.04 0.1 0.017</size>
                    </box>
                </geometry>
                <max_contacts>5</max_contacts>
                <surface>
                    <contact>
                        <ode>
                            <kp>1000000.0</kp>
                            <kd>1</kd>
                            <min_depth>0.01</min_depth>
                            <max_vel>1</max_vel>
                        </ode>
                    </contact>
                    <friction>
                        <ode>
                            <mu>1.16</mu>
                            <mu2>1.16</mu2>
                        </ode>
                    </friction>
                </surface>
            </collision>
            <visual name="gripper_hand_visual">
                <pose>0 0 0 1.570796327 0 1.570796327</pose>
                <geometry>
                    <mesh>
                        <scale>0.001 0.001 0.001</scale>
                        <uri>meshes/gripper2/gripper_hand.stl</uri>
                    </mesh>
                </geometry>
                <material>
                    <ambient>0.1 0.1 0.1 1</ambient>
                    <diffuse>0.3 0.3 0.3 1</diffuse>
                    <specular>1 1 1 1</specular>
                    <emissive>0 0 0 1</emissive>
                </material>
            </visual>
            <collision name="gripper_hand_sideL_collision">
                <pose>0 0.08 0.03 0 0 0</pose>
                <geometry>
                    <box>
                        <size>0.01 0.05 0.07</size>
                    </box>
                </geometry>
                <surface>
                    <contact>
                        <ode>
                            <kp>1000000.0</kp>
                            <kd>1</kd>
                            <min_depth>0.01</min_depth>
                            <max_vel>1</max_vel>
                        </ode>
                    </contact>
                    <friction>
                        <ode>
                            <mu>1.16</mu>
                            <mu2>1.16</mu2>
                        </ode>
                    </friction>
                </surface>
            </collision>
            <collision name="gripper_hand_sideL_slide_collision">
                <pose>0 0.055 0.03 0.9 0 0</pose>
                <geometry>
                    <box>
                        <size>0.01 0.055 0.04</size>
                    </box>
                </geometry>
                <surface>
                    <contact>
                        <ode>
                            <kp>1000000.0</kp>
                            <kd>1</kd>
                            <min_depth>0.01</min_depth>
                            <max_vel>1</max_vel>
                        </ode>
                    </contact>
                    <friction>
                        <ode>
                            <mu>0</mu>
                            <mu2>0</mu2>
                        </ode>
                    </friction>
                </surface>
            </collision>
            <collision name="gripper_hand_sideR_collision">
                <pose>0 -0.08 0.03 0 0 0</pose>
                <geometry>
                    <box>
                        <size>0.01 0.05 0.07</size>
                    </box>
                </geometry>
                <surface>
                    <contact>
                        <ode>
                            <kp>1000000.0</kp>
                            <kd>1</kd>
                            <min_depth>0.01</min_depth>
                            <max_vel>1</max_vel>
                        </ode>
                    </contact>
                    <friction>
                        <ode>
                            <mu>1.16</mu>
                            <mu2>1.16</mu2>
                        </ode>
                    </friction>
                </surface>
            </collision>
            <collision name="gripper_hand_sideR_slide_collision">
                <pose>0 -0.055 0.03 -0.9 0 0</pose>
                <geometry>
                    <box>
                        <size>0.01 0.055 0.04</size>
                    </box>
                </geometry>
                <surface>
                    <contact>
                        <ode>
                            <kp>1000000.0</kp>
                            <kd>1</kd>
                            <min_depth>0.01</min_depth>
                            <max_vel>1</max_vel>
                        </ode>
                    </contact>
                    <friction>
                        <ode>
                            <mu>0</mu>
                            <mu2>0</mu2>
                        </ode>
                    </friction>
                </surface>
            </collision>
        </link>
        <joint name="gripper_hand_joint" type="revolute">
            <pose>0.2 0 0 0 0 0</pose>
            <child>gripper_hand</child>
            <parent>gripper</parent>
            <axis>
                <xyz>0 1 0</xyz>
                <limit>
                    <lower>-0.35</lower>
                    <upper>0.1</upper>
                    <effort>100</effort>
                    <velocity>0.5</velocity>
                </limit>
            </axis>
        </joint>
        <!-- WHEELS -->
        <link name="wheel_front">
            <pose>0.145 0 0.0345 1.570796327 0 0</pose>
            <inertial>
                <pose>0 0 0 0 0 0</pose>
                <mass>0.1</mass>
                <inertia>
                    <ixx>0.0000175</ixx>
                    <ixy>0</ixy>
                    <ixz>0</ixz>
                    <iyy>0.0000175</iyy>
                    <iyz>0</iyz>
                    <izz>0.0000175</izz>
                </inertia>
            </inertial>
            <collision name="wheel_front_collision">
                <pose>0 0 0 0 0 0</pose>
                <geometry>
                    <sphere>
                        <radius>0.025</radius>
                    </sphere>
                </geometry>
                <max_contacts>2</max_contacts>
                <surface>
                    <contact>
                        <ode>
                            <kp>1000000.0</kp>
                            <kd>1</kd>
                            <min_depth>0.01</min_depth>
                            <max_vel>1</max_vel>
                        </ode>
                    </contact>
                    <friction>
                        <ode>
                            <mu>1.16</mu>
                            <mu2>1.16</mu2>
                        </ode>
                    </friction>
                </surface>
            </collision>
        </link>
        <joint name="wheel_front_joint" type="ball">
            <child>wheel_front</child>
            <parent>base_link</parent>
            <axis>
                <limit>
                    <effort>100</effort>
                </limit>
                <dynamics>
                    <spring_reference>0</spring_reference>
                    <spring_stiffness>0</spring_stiffness>
                    <damping>10</damping>
                </dynamics>
            </axis>
        </joint>
        <link name="wheel_back">
            <pose>-0.225 0 0.035 1.570796327 0 0</pose>
            <inertial>
                <pose>0 0 0 0 0 0</pose>
                <mass>0.1</mass>
                <inertia>
                    <ixx>0.0000175</ixx>
                    <ixy>0</ixy>
                    <ixz>0</ixz>
                    <iyy>0.0000175</iyy>
                    <iyz>0</iyz>
                    <izz>0.0000175</izz>
                </inertia>
            </inertial>
            <collision name="wheel_back_collision">
                <pose>0 0 0 0 0 0</pose>
                <geometry>
                    <sphere>
                        <radius>0.035</radius>
                    </sphere>
                </geometry>
                <max_contacts>2</max_contacts>
                <surface>
                    <contact>
                        <ode>
                            <kp>1000000.0</kp>
                            <kd>1</kd>
                            <min_depth>0.01</min_depth>
                            <max_vel>1</max_vel>
                        </ode>
                    </contact>
                    <friction>
                        <ode>
                            <mu>1.16</mu>
                            <mu2>1.16</mu2>
                        </ode>
                    </friction>
                </surface>
            </collision>
        </link>
        <joint name="wheel_back_joint" type="ball">
            <child>wheel_back</child>
            <parent>base_link</parent>
            <axis>
                <limit>
                    <effort>100</effort>
                </limit>
                <dynamics>
                    <spring_reference>0</spring_reference>
                    <spring_stiffness>0</spring_stiffness>
                    <damping>10</damping>
                </dynamics>
            </axis>
        </joint>
        <link name="wheel_left">
            <pose>0 0.257 0.195 -1.570796327 0 0</pose>
            <inertial>
                <pose>0 0 0 0 0 0</pose>
                <mass>0.1</mass>
                <inertia>
                    <ixx>0.0000175</ixx>
                    <ixy>0</ixy>
                    <ixz>0</ixz>
                    <iyy>0.0000175</iyy>
                    <iyz>0</iyz>
                    <izz>0.00003125</izz>
                </inertia>
            </inertial>
            <collision name="wheel_left_collision">
                <pose>0 0 0 0 0 0</pose>
                <geometry>
                    <cylinder>
                        <radius>0.195</radius>
                        <length>0.05</length>
                    </cylinder>
                </geometry>
                <max_contacts>5</max_contacts>
                <surface>
                    <contact>
                        <ode>
                            <kp>1000000.0</kp>
                            <kd>1</kd>
                            <min_depth>0.01</min_depth>
                            <max_vel>1</max_vel>
                        </ode>
                    </contact>
                    <friction>
                        <ode>
                            <mu>1.16</mu>
                            <mu2>10</mu2>
                            <fdir1>1 0 0</fdir1>
                        </ode>
                    </friction>
                </surface>
            </collision>
            <visual name="wheel_left_visual">
                <pose>0 0 -0.03 0 0 0</pose>
                <geometry>
                    <mesh>
                        <scale>0.98 0.98 1.0</scale>
                        <uri>meshes/wheel/wheel.dae</uri>
                    </mesh>
                </geometry>
            </visual>
        </link>
        <joint name="wheel_left_joint" type="revolute">
            <child>wheel_left</child>
            <parent>base_link</parent>
            <axis>
                <xyz>0 0 1</xyz>
                <limit>
                    <effort>9.6</effort>
                </limit>
                <dynamics>
                    <damping>3.0</damping>
                    <friction>0.5</friction>
                </dynamics>
            </axis>
        </joint>
        <link name="wheel_right">
            <pose>0 -0.257 0.195 1.570796327 0 0</pose>
            <inertial>
                <pose>0 0 0 0 0 0</pose>
                <mass>0.1</mass>
                <inertia>
                    <ixx>0.0000175</ixx>
                    <ixy>0</ixy>
                    <ixz>0</ixz>
                    <iyy>0.0000175</iyy>
                    <iyz>0</iyz>
                    <izz>0.00003125</izz>
                </inertia>
            </inertial>
            <collision name="wheel_right_collision">
                <pose>0 0 0 0 0 0</pose>
                <geometry>
                    <cylinder>
                        <radius>0.195</radius>
                        <length>0.05</length>
                    </cylinder>
                </geometry>
                <max_contacts>5</max_contacts>
                <surface>
                    <contact>
                        <ode>
                            <kp>1000000.0</kp>
                            <kd>1</kd>
                            <min_depth>0.01</min_depth>
                            <max_vel>1</max_vel>
                        </ode>
                    </contact>
                    <friction>
                        <ode>
                            <mu>1.16</mu>
                            <mu2>10</mu2>
                            <fdir1>1 0 0</fdir1>
                        </ode>
                    </friction>
                </surface>
            </collision>
            <visual name="wheel_right_visual">
                <pose>0 0 -0.03 0 0 0</pose>
                <geometry>
                    <mesh>
                        <scale>0.98 0.98 1.0</scale>
                        <uri>meshes/wheel/wheel.dae</uri>
                    </mesh>
                </geometry>
            </visual>
        </link>
        <joint name="wheel_right_joint" type="revolute">
            <child>wheel_right</child>
            <parent>base_link</parent>
            <axis>
                <xyz>0 0 -1</xyz>
                <limit>
                    <effort>9.6</effort>
                </limit>
                <dynamics>
                    <damping>3.0</damping>
                    <friction>0.5</friction>
                </dynamics>
            </axis>
        </joint>
        <!-- CONTROLERS PLUGINS -->
        <!-- DIFF DRIVE PLUGIN / WHEELS CONTROLER -->
        <plugin filename="ignition-gazebo-diff-drive-system" name="ignition::gazebo::systems::DiffDrive">
            <left_joint>wheel_left_joint</left_joint>
            <right_joint>wheel_right_joint</right_joint>
            <wheel_separation>0.5605</wheel_separation>
            <wheel_radius>0.195</wheel_radius>
            <odom_publish_frequency>20</odom_publish_frequency>
            <frame_id>odom</frame_id>
            <child_frame_id>base_link</child_frame_id>
        </plugin>
        <!-- GRIPPER RAIL CONTROLER -->
        <plugin filename="ignition-gazebo-joint-controller-system" name="ignition::gazebo::systems::JointController">
            <joint_name>gripper_joint</joint_name>
            <use_force_commands>true</use_force_commands>
            <p_gain>0.2</p_gain>
            <i_gain>0.01</i_gain>
        </plugin>
        <!-- GRIPPER ATTACH CONTROLER -->
        <plugin filename="ignition-gazebo-joint-controller-system" name="ignition::gazebo::systems::JointController">
            <joint_name>gripper_hand_joint</joint_name>
            <use_force_commands>true</use_force_commands>
            <p_gain>0.2</p_gain>
            <i_gain>0.01</i_gain>
        </plugin>
        <!-- GROUND ODOMETRY POSITION STATE PUBLISHER (FAKE LOCALIZATION) -->
        <plugin filename="ignition-gazebo-pose-publisher-system" name="ignition::gazebo::systems::PosePublisher">
            <publish_link_pose>true</publish_link_pose>
            <publish_collision_pose>false</publish_collision_pose>
            <publish_visual_pose>false</publish_visual_pose>
            <publish_sensor_pose>false</publish_sensor_pose>
            <publish_nested_model_pose>true</publish_nested_model_pose>
            <update_frequency>20</update_frequency>
        </plugin>
        <plugin filename="ignition-gazebo-joint-controller-system" name="ignition::gazebo::systems::JointController">
            <joint_name>warnign_light_joint</joint_name>
            <initial_velocity>10.0</initial_velocity>
        </plugin>
        <plugin filename="ignition-gazebo-linearbatteryplugin-system" name="ignition::gazebo::systems::LinearBatteryPlugin">
            <battery_name>linear_battery</battery_name>
            <voltage>24.592</voltage>
            <open_circuit_voltage_constant_coef>24.592</open_circuit_voltage_constant_coef>
            <capacity>1.2009</capacity>
            <power_load>6.5</power_load>
            <fix_issue_225>true</fix_issue_225>
            <enable_recharge>true</enable_recharge>
            <!-- charging I = c / t, discharging I = P / V, 
          charging I should be > discharging I -->
            <charging_time>3.0</charging_time>
            <!-- Consumer-specific -->
            <!-- <power_load>2.1</power_load> -->
            <recharge_by_topic>true</recharge_by_topic>
        </plugin>
        <plugin filename="ignition-gazebo-joint-state-publisher-system" name="ignition::gazebo::systems::JointStatePublisher">
            <joint_name>gripper_joint</joint_name>
            <joint_name>gripper_hand_joint</joint_name>
        </plugin>
    </model>
</sdf>
